Workbook

Sheet 01 Exec Summary
B2: DRAFT MANAGEMENT REPORT — 16/16 ENTITIES VALIDATED AGAINST CASEWARE | J2: Select Fiscal Year | K2: FY2025
B4: Sandhu Group — Consolidated Performance Report
B6: 16 entities · Restaurant, Real Estate, Investments, Construction, Hotel & Rental · FY ended March 31 · Prepared for group management review
B8: 01 Executive Summary | D8: 02 Profitability | F8: 03 Group Summary | H8: 04 Tax Position | J8: 05 Debt & Liquidity | L8: 06 Wealth of Group | N8: 07 Reorg & LCGE | P8: 08 Risk & Alerts
B11: ="The one-page summary — six headline numbers below, each labelled with its data confidence so nothing is trusted more than it should be. The Select Fiscal Year box above (top right) drives every group-wide view — this page's own KPI cards, the industry table below, Entity Register and Group Summary — currently showing "&$K$2&". 02 Profitability has its own separate fiscal-year selector for drilling into one entity's history without changing the group-wide numbers here. The trend sections further down (Notable Movers, the revenue/EBITDA chart) stay fixed to FY2023→FY2025 regardless of either selector."
B14: GROUP REVENUE | D14: GROUP EBITDA | F14: CONSOLIDATED EFF. TAX RATE | H14: ENTITIES IN LOSS POSITION | J14: GROUP NET WORTH | L14: SBD UTILIZATION (14 OF 16)
B15: =SUM('Entity Register'!C5:C20) | D15: =SUM('Entity Register'!J5:J20) | F15: =IFERROR(SUM('Entity Register'!I5:I20)/(SUM('Entity Register'!K5:K20)+SUM('Entity Register'!I5:I20)),0) | H15: =COUNTIF('Entity Register'!K5:K20,"<0")&" / "&COUNTA('Entity Register'!A5:A20) | J15: ="pending" | L15: =78035
B17: =TEXT((SUM('Entity Register'!C5:C20)-(-SUMIFS(Fact_TrialBalance[Amount],Fact_TrialBalance[Category],"Operating Revenue",Fact_TrialBalance[FiscalYear],"FY2023")))/(-SUMIFS(Fact_TrialBalance[Amount],Fact_TrialBalance[Category],"Operating Revenue",Fact_TrialBalance[FiscalYear],"FY2023")),"+0.0%;-0.0%")&" vs FY2023" | D17: =TEXT(SUM('Entity Register'!J5:J20)/SUM('Entity Register'!C5:C20),"0.0%")&" margin" | H17: =TEXT(COUNTIF('Entity Register'!K5:K20,"<0")/COUNTA('Entity Register'!A5:A20),"0%")&" of group" | J17: needs CaseWare balance sheets | L17: 15.6% of $500,000, excl. 2 entities' own claims
B20: Data confidence
B21: ● | C21: P&L (16/16 entities) — every entity rebuilt fresh from its raw CaseWare WTB and validated to the penny (FY2025 Net Income matches the project's Validation Log exactly for all of them).
B22: ● | C22: SBD & GRIP — real, cross-checked against Corporate Taxprep (14 of 16 entities; excludes IndiaRosa 2 & Sandhu & Sandhu's own claims, not found in that export).
B23: ● | C23: RDTOH & CDA — confirmed NOT present in the Taxprep export tested (see 04 Tax Position).
B24: ● | C24: Balance sheet / consolidated net worth — not available; the WTB export is income-statement only.
B25: ● | C25: One unexpected entity (9475-3381 Québec Inc.) appears in the Taxprep data but has no WTB and isn't in scope — needs your confirmation on whether it belongs in the group.
B26: ● | C26: Group-level Revenue/EBITDA are within ~0.5%/1.8% of the Section 6 benchmark despite every entity's own Net Income matching exactly — a small residual category difference likely remains in 1–2 entities (see Notes & Validation).
B28: Notable movers, FY2023 → FY2025
B29: BIGGEST IMPROVEMENT | H29: BIGGEST DECLINE
B30: 9455-4201 Québec Inc. - Sandhu G | H30: 9366-1676 Québec Inc. - Sandhu G.
B31: Net income: $-2,970 → $571,535 (+574,505) | H31: Net income: $-84,716 → $-660,352 (-575,636)
B33: Management commentary
B34: Auto-generated from FY2023 → FY2025 movement — every figure ties to the raw WTB data.
B35: ="— Group revenue grew from $"&TEXT(-SUMIFS(Fact_TrialBalance[Amount],Fact_TrialBalance[Category],"Operating Revenue",Fact_TrialBalance[FiscalYear],"FY2023"),"#,##0")&" (FY2023) to $"&TEXT(-SUMIFS(Fact_TrialBalance[Amount],Fact_TrialBalance[Category],"Operating Revenue",Fact_TrialBalance[FiscalYear],"FY2025"),"#,##0")&" (FY2025), up "&TEXT((-SUMIFS(Fact_TrialBalance[Amount],Fact_TrialBalance[Category],"Operating Revenue",Fact_TrialBalance[FiscalYear],"FY2025")/-SUMIFS(Fact_TrialBalance[Amount],Fact_TrialBalance[Category],"Operating Revenue",Fact_TrialBalance[FiscalYear],"FY2023"))-1,"0.0%")&"."
B36: ="— Group EBITDA margin moved from 17.9% (FY2023) to 18.3% (FY2025)."
B37: ="— Consolidated effective tax rate moved from 10.9% (FY2023) to 19.4% (FY2025)."
B38: ="— Entities in a loss position: 6 of 16 in FY2023, versus "&COUNTIF('Entity Register'!K5:K20,"<0")&" of "&COUNTA('Entity Register'!A5:A20)&" in FY2025."
B39: ="— SBD: $78,035 of the $500,000 federal limit accounted for across the 14 associated corporations with data in IndiaRosa 2's Taxprep export — IndiaRosa 2's and Sandhu & Sandhu's own claims are not in that export, so this is a floor, not the group total."
B40: ="— Biggest mover: 9455-4201 Québec Inc. - Sandhu G (net income +$574,505) vs. 9366-1676 Québec Inc. - Sandhu G. (-575,636)."
B42: Group revenue & EBITDA, FY2023 vs FY2025
B43: FiscalYear | C43: Revenue | D43: EBITDA
B44: FY2023 | C44: =-SUMIFS(Fact_TrialBalance[Amount],Fact_TrialBalance[Category],"Operating Revenue",Fact_TrialBalance[FiscalYear],"FY2023") | D44: =-(SUMIFS(Fact_TrialBalance[Amount],Fact_TrialBalance[FiscalYear],"FY2023")-SUMPRODUCT((Fact_TrialBalance[FiscalYear]="FY2023")*(ISNUMBER(MATCH(Fact_TrialBalance[Category],{"Interest & Financing","Amortization","Income Tax"},0)))*Fact_TrialBalance[Amount]))
B45: FY2025 | C45: =-SUMIFS(Fact_TrialBalance[Amount],Fact_TrialBalance[Category],"Operating Revenue",Fact_TrialBalance[FiscalYear],"FY2025") | D45: =-(SUMIFS(Fact_TrialBalance[Amount],Fact_TrialBalance[FiscalYear],"FY2025")-SUMPRODUCT((Fact_TrialBalance[FiscalYear]="FY2025")*(ISNUMBER(MATCH(Fact_TrialBalance[Category],{"Interest & Financing","Amortization","Income Tax"},0)))*Fact_TrialBalance[Amount]))
B63: ="Performance by industry, "&$K$2
B64: Industry | C64: # Entities | D64: Revenue | E64: EBITDA | F64: Margin
B65: Construction | C65: =COUNTIF(Dim_Entity[Industry],"Construction") | D65: =-SUMIFS(Fact_TrialBalance[Amount],Fact_TrialBalance[Industry],"Construction",Fact_TrialBalance[Category],"Operating Revenue",Fact_TrialBalance[FiscalYear],$K$2)-SUMIFS(Fact_TrialBalance[Amount],Fact_TrialBalance[Industry],"Construction",Fact_TrialBalance[Category],"Investment & Other Income",Fact_TrialBalance[FiscalYear],$K$2) | E65: =-(SUMIFS(Fact_TrialBalance[Amount],Fact_TrialBalance[Industry],"Construction",Fact_TrialBalance[FiscalYear],$K$2)-SUMPRODUCT((Fact_TrialBalance[Industry]="Construction")*(Fact_TrialBalance[FiscalYear]=$K$2)*(ISNUMBER(MATCH(Fact_TrialBalance[Category],{"Interest & Financing","Amortization","Income Tax"},0)))*Fact_TrialBalance[Amount])) | F65: =IFERROR(E65/D65,0)
B66: Hotel | C66: =COUNTIF(Dim_Entity[Industry],"Hotel") | D66: =-SUMIFS(Fact_TrialBalance[Amount],Fact_TrialBalance[Industry],"Hotel",Fact_TrialBalance[Category],"Operating Revenue",Fact_TrialBalance[FiscalYear],$K$2)-SUMIFS(Fact_TrialBalance[Amount],Fact_TrialBalance[Industry],"Hotel",Fact_TrialBalance[Category],"Investment & Other Income",Fact_TrialBalance[FiscalYear],$K$2) | E66: =-(SUMIFS(Fact_TrialBalance[Amount],Fact_TrialBalance[Industry],"Hotel",Fact_TrialBalance[FiscalYear],$K$2)-SUMPRODUCT((Fact_TrialBalance[Industry]="Hotel")*(Fact_TrialBalance[FiscalYear]=$K$2)*(ISNUMBER(MATCH(Fact_TrialBalance[Category],{"Interest & Financing","Amortization","Income Tax"},0)))*Fact_TrialBalance[Amount])) | F66: =IFERROR(E66/D66,0)
B67: Investments | C67: =COUNTIF(Dim_Entity[Industry],"Investments") | D67: =-SUMIFS(Fact_TrialBalance[Amount],Fact_TrialBalance[Industry],"Investments",Fact_TrialBalance[Category],"Operating Revenue",Fact_TrialBalance[FiscalYear],$K$2)-SUMIFS(Fact_TrialBalance[Amount],Fact_TrialBalance[Industry],"Investments",Fact_TrialBalance[Category],"Investment & Other Income",Fact_TrialBalance[FiscalYear],$K$2) | E67: =-(SUMIFS(Fact_TrialBalance[Amount],Fact_TrialBalance[Industry],"Investments",Fact_TrialBalance[FiscalYear],$K$2)-SUMPRODUCT((Fact_TrialBalance[Industry]="Investments")*(Fact_TrialBalance[FiscalYear]=$K$2)*(ISNUMBER(MATCH(Fact_TrialBalance[Category],{"Interest & Financing","Amortization","Income Tax"},0)))*Fact_TrialBalance[Amount])) | F67: =IFERROR(E67/D67,0)
B68: Real estate | C68: =COUNTIF(Dim_Entity[Industry],"Real estate") | D68: =-SUMIFS(Fact_TrialBalance[Amount],Fact_TrialBalance[Industry],"Real estate",Fact_TrialBalance[Category],"Operating Revenue",Fact_TrialBalance[FiscalYear],$K$2)-SUMIFS(Fact_TrialBalance[Amount],Fact_TrialBalance[Industry],"Real estate",Fact_TrialBalance[Category],"Investment & Other Income",Fact_TrialBalance[FiscalYear],$K$2) | E68: =-(SUMIFS(Fact_TrialBalance[Amount],Fact_TrialBalance[Industry],"Real estate",Fact_TrialBalance[FiscalYear],$K$2)-SUMPRODUCT((Fact_TrialBalance[Industry]="Real estate")*(Fact_TrialBalance[FiscalYear]=$K$2)*(ISNUMBER(MATCH(Fact_TrialBalance[Category],{"Interest & Financing","Amortization","Income Tax"},0)))*Fact_TrialBalance[Amount])) | F68: =IFERROR(E68/D68,0)
B69: Rental | C69: =COUNTIF(Dim_Entity[Industry],"Rental") | D69: =-SUMIFS(Fact_TrialBalance[Amount],Fact_TrialBalance[Industry],"Rental",Fact_TrialBalance[Category],"Operating Revenue",Fact_TrialBalance[FiscalYear],$K$2)-SUMIFS(Fact_TrialBalance[Amount],Fact_TrialBalance[Industry],"Rental",Fact_TrialBalance[Category],"Investment & Other Income",Fact_TrialBalance[FiscalYear],$K$2) | E69: =-(SUMIFS(Fact_TrialBalance[Amount],Fact_TrialBalance[Industry],"Rental",Fact_TrialBalance[FiscalYear],$K$2)-SUMPRODUCT((Fact_TrialBalance[Industry]="Rental")*(Fact_TrialBalance[FiscalYear]=$K$2)*(ISNUMBER(MATCH(Fact_TrialBalance[Category],{"Interest & Financing","Amortization","Income Tax"},0)))*Fact_TrialBalance[Amount])) | F69: =IFERROR(E69/D69,0)
B70: Restaurant | C70: =COUNTIF(Dim_Entity[Industry],"Restaurant") | D70: =-SUMIFS(Fact_TrialBalance[Amount],Fact_TrialBalance[Industry],"Restaurant",Fact_TrialBalance[Category],"Operating Revenue",Fact_TrialBalance[FiscalYear],$K$2)-SUMIFS(Fact_TrialBalance[Amount],Fact_TrialBalance[Industry],"Restaurant",Fact_TrialBalance[Category],"Investment & Other Income",Fact_TrialBalance[FiscalYear],$K$2) | E70: =-(SUMIFS(Fact_TrialBalance[Amount],Fact_TrialBalance[Industry],"Restaurant",Fact_TrialBalance[FiscalYear],$K$2)-SUMPRODUCT((Fact_TrialBalance[Industry]="Restaurant")*(Fact_TrialBalance[FiscalYear]=$K$2)*(ISNUMBER(MATCH(Fact_TrialBalance[Category],{"Interest & Financing","Amortization","Income Tax"},0)))*Fact_TrialBalance[Amount])) | F70: =IFERROR(E70/D70,0)
B71: "Revenue" here = Operating Revenue + Investment & Other Income, matching EBITDA's income scope — HoldCos earn mainly via intercompany dividends/interest.

Sheet 02 Profitability
B1: ← 01 Exec Summary
B2: SANDHU GROUP — Financial Dashboard
B4: CaseWare WTB + GIFI categorization • Fiscal year end March 31 • Figures in CAD
B6: Select Entity | C6: Restaurant Indiarosa II | G6: Fiscal Year (this page) | H6: FY2025 | I6: independent of 01 Exec Summary's selector — see note
B8: EntityId -> | C8: =INDEX(Dim_Entity!$A$2:$A$17,MATCH($C$6,Dim_Entity!$B$2:$B$17,0))
B10: REVENUE | D10: EBITDA | G10: NET INCOME | I10: INCOME TAX
B11: =-(SUMIFS(Fact_TrialBalance[Amount],Fact_TrialBalance[EntityId],$C$8,Fact_TrialBalance[Category],"Operating Revenue",Fact_TrialBalance[FiscalYear],$H$6)) | D11: =-(SUMIFS(Fact_TrialBalance[Amount],Fact_TrialBalance[EntityId],$C$8,Fact_TrialBalance[FiscalYear],$H$6)-SUMPRODUCT((Fact_TrialBalance[EntityId]=$C$8)*(Fact_TrialBalance[FiscalYear]=$H$6)*(ISNUMBER(MATCH(Fact_TrialBalance[Category],{"Interest & Financing","Amortization","Income Tax"},0)))*Fact_TrialBalance[Amount])) | G11: =-(SUMIFS(Fact_TrialBalance[Amount],Fact_TrialBalance[EntityId],$C$8,Fact_TrialBalance[FiscalYear],$H$6)) | I11: =SUMIFS(Fact_TrialBalance[Amount],Fact_TrialBalance[EntityId],$C$8,Fact_TrialBalance[Category],"Income Tax",Fact_TrialBalance[FiscalYear],$H$6)
B14: EBITDA MARGIN | D14: EFFECTIVE TAX RATE | G14: % OF GROUP REVENUE | I14: COGS
B15: =IFERROR(D11/B11,0) | D15: =IFERROR(I11/(G11+I11),0) | G15: =IFERROR(B11/(-SUMIFS(Fact_TrialBalance[Amount],Fact_TrialBalance[Category],"Operating Revenue",Fact_TrialBalance[FiscalYear],$H$6)),0) | I15: =SUMIFS(Fact_TrialBalance[Amount],Fact_TrialBalance[EntityId],$C$8,Fact_TrialBalance[Category],"COGS",Fact_TrialBalance[FiscalYear],$H$6)
B19: Category Breakdown
B20: Category | C20: Amount
B21: Operating Revenue | C21: =-(SUMIFS(Fact_TrialBalance[Amount],Fact_TrialBalance[EntityId],$C$8,Fact_TrialBalance[Category],"Operating Revenue",Fact_TrialBalance[FiscalYear],$H$6))
B22: Investment & Other Income | C22: =-(SUMIFS(Fact_TrialBalance[Amount],Fact_TrialBalance[EntityId],$C$8,Fact_TrialBalance[Category],"Investment & Other Income",Fact_TrialBalance[FiscalYear],$H$6))
B23: COGS | C23: =SUMIFS(Fact_TrialBalance[Amount],Fact_TrialBalance[EntityId],$C$8,Fact_TrialBalance[Category],"COGS",Fact_TrialBalance[FiscalYear],$H$6)
B24: Payroll & Benefits | C24: =SUMIFS(Fact_TrialBalance[Amount],Fact_TrialBalance[EntityId],$C$8,Fact_TrialBalance[Category],"Payroll & Benefits",Fact_TrialBalance[FiscalYear],$H$6)
B25: Occupancy | C25: =SUMIFS(Fact_TrialBalance[Amount],Fact_TrialBalance[EntityId],$C$8,Fact_TrialBalance[Category],"Occupancy",Fact_TrialBalance[FiscalYear],$H$6)
B26: Marketing & Entertainment | C26: =SUMIFS(Fact_TrialBalance[Amount],Fact_TrialBalance[EntityId],$C$8,Fact_TrialBalance[Category],"Marketing & Entertainment",Fact_TrialBalance[FiscalYear],$H$6)
B27: Administrative | C27: =SUMIFS(Fact_TrialBalance[Amount],Fact_TrialBalance[EntityId],$C$8,Fact_TrialBalance[Category],"Administrative",Fact_TrialBalance[FiscalYear],$H$6)
B28: Management Fees (Interco) | C28: =SUMIFS(Fact_TrialBalance[Amount],Fact_TrialBalance[EntityId],$C$8,Fact_TrialBalance[Category],"Management Fees (Interco)",Fact_TrialBalance[FiscalYear],$H$6)
B29: Interest & Financing | C29: =SUMIFS(Fact_TrialBalance[Amount],Fact_TrialBalance[EntityId],$C$8,Fact_TrialBalance[Category],"Interest & Financing",Fact_TrialBalance[FiscalYear],$H$6)
B30: Repairs & Maintenance | C30: =SUMIFS(Fact_TrialBalance[Amount],Fact_TrialBalance[EntityId],$C$8,Fact_TrialBalance[Category],"Repairs & Maintenance",Fact_TrialBalance[FiscalYear],$H$6)
B31: Amortization | C31: =SUMIFS(Fact_TrialBalance[Amount],Fact_TrialBalance[EntityId],$C$8,Fact_TrialBalance[Category],"Amortization",Fact_TrialBalance[FiscalYear],$H$6)
B32: Other Operating | C32: =SUMIFS(Fact_TrialBalance[Amount],Fact_TrialBalance[EntityId],$C$8,Fact_TrialBalance[Category],"Other Operating",Fact_TrialBalance[FiscalYear],$H$6)
B33: Income Tax | C33: =SUMIFS(Fact_TrialBalance[Amount],Fact_TrialBalance[EntityId],$C$8,Fact_TrialBalance[Category],"Income Tax",Fact_TrialBalance[FiscalYear],$H$6)
B36: Key Ratios — Common-Size P&L (% of Revenue), Selected Entity vs Group, Same Year
B37: Category | C37: This Entity | D37: Group Avg | E37: vs Group (pp)
B38: COGS | C38: =IFERROR((SUMIFS(Fact_TrialBalance[Amount],Fact_TrialBalance[EntityId],$C$8,Fact_TrialBalance[Category],"COGS",Fact_TrialBalance[FiscalYear],$H$6))/(-(SUMIFS(Fact_TrialBalance[Amount],Fact_TrialBalance[EntityId],$C$8,Fact_TrialBalance[Category],"Operating Revenue",Fact_TrialBalance[FiscalYear],$H$6))),0) | D38: =IFERROR((SUMIFS(Fact_TrialBalance[Amount],Fact_TrialBalance[Category],"COGS",Fact_TrialBalance[FiscalYear],$H$6))/(-(SUMIFS(Fact_TrialBalance[Amount],Fact_TrialBalance[Category],"Operating Revenue",Fact_TrialBalance[FiscalYear],$H$6))),0) | E38: =C38-D38
B39: Payroll & Benefits | C39: =IFERROR((SUMIFS(Fact_TrialBalance[Amount],Fact_TrialBalance[EntityId],$C$8,Fact_TrialBalance[Category],"Payroll & Benefits",Fact_TrialBalance[FiscalYear],$H$6))/(-(SUMIFS(Fact_TrialBalance[Amount],Fact_TrialBalance[EntityId],$C$8,Fact_TrialBalance[Category],"Operating Revenue",Fact_TrialBalance[FiscalYear],$H$6))),0) | D39: =IFERROR((SUMIFS(Fact_TrialBalance[Amount],Fact_TrialBalance[Category],"Payroll & Benefits",Fact_TrialBalance[FiscalYear],$H$6))/(-(SUMIFS(Fact_TrialBalance[Amount],Fact_TrialBalance[Category],"Operating Revenue",Fact_TrialBalance[FiscalYear],$H$6))),0) | E39: =C39-D39
B40: Occupancy | C40: =IFERROR((SUMIFS(Fact_TrialBalance[Amount],Fact_TrialBalance[EntityId],$C$8,Fact_TrialBalance[Category],"Occupancy",Fact_TrialBalance[FiscalYear],$H$6))/(-(SUMIFS(Fact_TrialBalance[Amount],Fact_TrialBalance[EntityId],$C$8,Fact_TrialBalance[Category],"Operating Revenue",Fact_TrialBalance[FiscalYear],$H$6))),0) | D40: =IFERROR((SUMIFS(Fact_TrialBalance[Amount],Fact_TrialBalance[Category],"Occupancy",Fact_TrialBalance[FiscalYear],$H$6))/(-(SUMIFS(Fact_TrialBalance[Amount],Fact_TrialBalance[Category],"Operating Revenue",Fact_TrialBalance[FiscalYear],$H$6))),0) | E40: =C40-D40
B41: Marketing & Entertainment | C41: =IFERROR((SUMIFS(Fact_TrialBalance[Amount],Fact_TrialBalance[EntityId],$C$8,Fact_TrialBalance[Category],"Marketing & Entertainment",Fact_TrialBalance[FiscalYear],$H$6))/(-(SUMIFS(Fact_TrialBalance[Amount],Fact_TrialBalance[EntityId],$C$8,Fact_TrialBalance[Category],"Operating Revenue",Fact_TrialBalance[FiscalYear],$H$6))),0) | D41: =IFERROR((SUMIFS(Fact_TrialBalance[Amount],Fact_TrialBalance[Category],"Marketing & Entertainment",Fact_TrialBalance[FiscalYear],$H$6))/(-(SUMIFS(Fact_TrialBalance[Amount],Fact_TrialBalance[Category],"Operating Revenue",Fact_TrialBalance[FiscalYear],$H$6))),0) | E41: =C41-D41
B42: Administrative | C42: =IFERROR((SUMIFS(Fact_TrialBalance[Amount],Fact_TrialBalance[EntityId],$C$8,Fact_TrialBalance[Category],"Administrative",Fact_TrialBalance[FiscalYear],$H$6))/(-(SUMIFS(Fact_TrialBalance[Amount],Fact_TrialBalance[EntityId],$C$8,Fact_TrialBalance[Category],"Operating Revenue",Fact_TrialBalance[FiscalYear],$H$6))),0) | D42: =IFERROR((SUMIFS(Fact_TrialBalance[Amount],Fact_TrialBalance[Category],"Administrative",Fact_TrialBalance[FiscalYear],$H$6))/(-(SUMIFS(Fact_TrialBalance[Amount],Fact_TrialBalance[Category],"Operating Revenue",Fact_TrialBalance[FiscalYear],$H$6))),0) | E42: =C42-D42
B43: Management Fees (Interco) | C43: =IFERROR((SUMIFS(Fact_TrialBalance[Amount],Fact_TrialBalance[EntityId],$C$8,Fact_TrialBalance[Category],"Management Fees (Interco)",Fact_TrialBalance[FiscalYear],$H$6))/(-(SUMIFS(Fact_TrialBalance[Amount],Fact_TrialBalance[EntityId],$C$8,Fact_TrialBalance[Category],"Operating Revenue",Fact_TrialBalance[FiscalYear],$H$6))),0) | D43: =IFERROR((SUMIFS(Fact_TrialBalance[Amount],Fact_TrialBalance[Category],"Management Fees (Interco)",Fact_TrialBalance[FiscalYear],$H$6))/(-(SUMIFS(Fact_TrialBalance[Amount],Fact_TrialBalance[Category],"Operating Revenue",Fact_TrialBalance[FiscalYear],$H$6))),0) | E43: =C43-D43
B44: Interest & Financing | C44: =IFERROR((SUMIFS(Fact_TrialBalance[Amount],Fact_TrialBalance[EntityId],$C$8,Fact_TrialBalance[Category],"Interest & Financing",Fact_TrialBalance[FiscalYear],$H$6))/(-(SUMIFS(Fact_TrialBalance[Amount],Fact_TrialBalance[EntityId],$C$8,Fact_TrialBalance[Category],"Operating Revenue",Fact_TrialBalance[FiscalYear],$H$6))),0) | D44: =IFERROR((SUMIFS(Fact_TrialBalance[Amount],Fact_TrialBalance[Category],"Interest & Financing",Fact_TrialBalance[FiscalYear],$H$6))/(-(SUMIFS(Fact_TrialBalance[Amount],Fact_TrialBalance[Category],"Operating Revenue",Fact_TrialBalance[FiscalYear],$H$6))),0) | E44: =C44-D44
B45: Repairs & Maintenance | C45: =IFERROR((SUMIFS(Fact_TrialBalance[Amount],Fact_TrialBalance[EntityId],$C$8,Fact_TrialBalance[Category],"Repairs & Maintenance",Fact_TrialBalance[FiscalYear],$H$6))/(-(SUMIFS(Fact_TrialBalance[Amount],Fact_TrialBalance[EntityId],$C$8,Fact_TrialBalance[Category],"Operating Revenue",Fact_TrialBalance[FiscalYear],$H$6))),0) | D45: =IFERROR((SUMIFS(Fact_TrialBalance[Amount],Fact_TrialBalance[Category],"Repairs & Maintenance",Fact_TrialBalance[FiscalYear],$H$6))/(-(SUMIFS(Fact_TrialBalance[Amount],Fact_TrialBalance[Category],"Operating Revenue",Fact_TrialBalance[FiscalYear],$H$6))),0) | E45: =C45-D45
B46: Amortization | C46: =IFERROR((SUMIFS(Fact_TrialBalance[Amount],Fact_TrialBalance[EntityId],$C$8,Fact_TrialBalance[Category],"Amortization",Fact_TrialBalance[FiscalYear],$H$6))/(-(SUMIFS(Fact_TrialBalance[Amount],Fact_TrialBalance[EntityId],$C$8,Fact_TrialBalance[Category],"Operating Revenue",Fact_TrialBalance[FiscalYear],$H$6))),0) | D46: =IFERROR((SUMIFS(Fact_TrialBalance[Amount],Fact_TrialBalance[Category],"Amortization",Fact_TrialBalance[FiscalYear],$H$6))/(-(SUMIFS(Fact_TrialBalance[Amount],Fact_TrialBalance[Category],"Operating Revenue",Fact_TrialBalance[FiscalYear],$H$6))),0) | E46: =C46-D46
B47: Other Operating | C47: =IFERROR((SUMIFS(Fact_TrialBalance[Amount],Fact_TrialBalance[EntityId],$C$8,Fact_TrialBalance[Category],"Other Operating",Fact_TrialBalance[FiscalYear],$H$6))/(-(SUMIFS(Fact_TrialBalance[Amount],Fact_TrialBalance[EntityId],$C$8,Fact_TrialBalance[Category],"Operating Revenue",Fact_TrialBalance[FiscalYear],$H$6))),0) | D47: =IFERROR((SUMIFS(Fact_TrialBalance[Amount],Fact_TrialBalance[Category],"Other Operating",Fact_TrialBalance[FiscalYear],$H$6))/(-(SUMIFS(Fact_TrialBalance[Amount],Fact_TrialBalance[Category],"Operating Revenue",Fact_TrialBalance[FiscalYear],$H$6))),0) | E47: =C47-D47
B48: Income Tax | C48: =IFERROR((SUMIFS(Fact_TrialBalance[Amount],Fact_TrialBalance[EntityId],$C$8,Fact_TrialBalance[Category],"Income Tax",Fact_TrialBalance[FiscalYear],$H$6))/(-(SUMIFS(Fact_TrialBalance[Amount],Fact_TrialBalance[EntityId],$C$8,Fact_TrialBalance[Category],"Operating Revenue",Fact_TrialBalance[FiscalYear],$H$6))),0) | D48: =IFERROR((SUMIFS(Fact_TrialBalance[Amount],Fact_TrialBalance[Category],"Income Tax",Fact_TrialBalance[FiscalYear],$H$6))/(-(SUMIFS(Fact_TrialBalance[Amount],Fact_TrialBalance[Category],"Operating Revenue",Fact_TrialBalance[FiscalYear],$H$6))),0) | E48: =C48-D48
B50: Gross Margin | C50: =IFERROR((-(SUMIFS(Fact_TrialBalance[Amount],Fact_TrialBalance[EntityId],$C$8,Fact_TrialBalance[Category],"Operating Revenue",Fact_TrialBalance[FiscalYear],$H$6))-(SUMIFS(Fact_TrialBalance[Amount],Fact_TrialBalance[EntityId],$C$8,Fact_TrialBalance[Category],"COGS",Fact_TrialBalance[FiscalYear],$H$6)))/(-(SUMIFS(Fact_TrialBalance[Amount],Fact_TrialBalance[EntityId],$C$8,Fact_TrialBalance[Category],"Operating Revenue",Fact_TrialBalance[FiscalYear],$H$6))),0) | D50: =IFERROR((-(SUMIFS(Fact_TrialBalance[Amount],Fact_TrialBalance[Category],"Operating Revenue",Fact_TrialBalance[FiscalYear],$H$6))-(SUMIFS(Fact_TrialBalance[Amount],Fact_TrialBalance[Category],"COGS",Fact_TrialBalance[FiscalYear],$H$6)))/(-(SUMIFS(Fact_TrialBalance[Amount],Fact_TrialBalance[Category],"Operating Revenue",Fact_TrialBalance[FiscalYear],$H$6))),0) | E50: =C50-D50
B51: EBITDA Margin | C51: =B15
B52: Net Margin | C52: =IFERROR(-(SUMIFS(Fact_TrialBalance[Amount],Fact_TrialBalance[EntityId],$C$8,Fact_TrialBalance[FiscalYear],$H$6))/(-(SUMIFS(Fact_TrialBalance[Amount],Fact_TrialBalance[EntityId],$C$8,Fact_TrialBalance[Category],"Operating Revenue",Fact_TrialBalance[FiscalYear],$H$6))),0)
...

Sheet 03 Group Summary
B1: ← 01 Exec Summary
B2: GROUP SUMMARY — ALL ENTITIES, ONE FISCAL YEAR | J2: Showing | K2: ='01 Exec Summary'!$K$2
B4: Sandhu Group — Group Summary
B6: ="16-entity group total (per Entity Register), fiscal year "&'01 Exec Summary'!$K$2&" — full scope, 2 family trusts excluded. Change the year on 01 Exec Summary."
B9: GROUP REVENUE | D9: GROUP EBITDA | F9: GROUP NET INCOME | H9: GROUP INCOME TAX | J9: EFFECTIVE TAX RATE
B10: =SUM('Entity Register'!C5:C20) | D10: =SUM('Entity Register'!J5:J20) | F10: =SUM('Entity Register'!K5:K20) | H10: =SUM('Entity Register'!I5:I20) | J10: =IFERROR(SUM('Entity Register'!I5:I20)/(SUM('Entity Register'!K5:K20)+SUM('Entity Register'!I5:I20)),0)
D12: =TEXT(SUM('Entity Register'!J5:J20)/SUM('Entity Register'!C5:C20),"0.0%")&" margin"
B15: ENTITIES IN MODEL | D15: ENTITIES IN LOSS POSITION | F15: TOP PERFORMER | I15: BIGGEST LOSS
B16: =COUNTA('Entity Register'!A5:A20) | D16: =COUNTIF('Entity Register'!K5:K20,"<0")&" / "&COUNTA('Entity Register'!A5:A20) | F16: =INDEX('Entity Register'!A5:A20,MATCH(MAX('Entity Register'!K5:K20),'Entity Register'!K5:K20,0)) | I16: =INDEX('Entity Register'!A5:A20,MATCH(MIN('Entity Register'!K5:K20),'Entity Register'!K5:K20,0))
B21: Entity Leaderboard — ranked by Net Income
B22: Rank | C22: Entity | D22: Industry | E22: Revenue | F22: EBITDA | G22: EBITDA Margin | H22: Net Income
B23: 1 | C23: ='Entity Register'!A10 | D23: Investments | E23: ='Entity Register'!C10 | F23: ='Entity Register'!J10 | G23: =IF(E23=0,"n/m",F23/E23) | H23: ='Entity Register'!K10
B24: 2 | C24: ='Entity Register'!A15 | D24: Restaurant | E24: ='Entity Register'!C15 | F24: ='Entity Register'!J15 | G24: =IF(E24=0,"n/m",F24/E24) | H24: ='Entity Register'!K15
B25: 3 | C25: ='Entity Register'!A11 | D25: Hotel | E25: ='Entity Register'!C11 | F25: ='Entity Register'!J11 | G25: =IF(E25=0,"n/m",F25/E25) | H25: ='Entity Register'!K11
B26: 4 | C26: ='Entity Register'!A17 | D26: Restaurant | E26: ='Entity Register'!C17 | F26: ='Entity Register'!J17 | G26: =IF(E26=0,"n/m",F26/E26) | H26: ='Entity Register'!K17
B27: 5 | C27: ='Entity Register'!A7 | D27: Real estate | E27: ='Entity Register'!C7 | F27: ='Entity Register'!J7 | G27: =IF(E27=0,"n/m",F27/E27) | H27: ='Entity Register'!K7
B28: 6 | C28: ='Entity Register'!A19 | D28: Rental | E28: ='Entity Register'!C19 | F28: ='Entity Register'!J19 | G28: =IF(E28=0,"n/m",F28/E28) | H28: ='Entity Register'!K19
B29: 7 | C29: ='Entity Register'!A9 | D29: Investments | E29: ='Entity Register'!C9 | F29: ='Entity Register'!J9 | G29: =IF(E29=0,"n/m",F29/E29) | H29: ='Entity Register'!K9
B30: 8 | C30: ='Entity Register'!A8 | D30: Investments | E30: ='Entity Register'!C8 | F30: ='Entity Register'!J8 | G30: =IF(E30=0,"n/m",F30/E30) | H30: ='Entity Register'!K8
B31: 9 | C31: ='Entity Register'!A5 | D31: Construction | E31: ='Entity Register'!C5 | F31: ='Entity Register'!J5 | G31: =IF(E31=0,"n/m",F31/E31) | H31: ='Entity Register'!K5
B32: 10 | C32: ='Entity Register'!A16 | D32: Restaurant | E32: ='Entity Register'!C16 | F32: ='Entity Register'!J16 | G32: =IF(E32=0,"n/m",F32/E32) | H32: ='Entity Register'!K16
B33: 11 | C33: ='Entity Register'!A20 | D33: Rental | E33: ='Entity Register'!C20 | F33: ='Entity Register'!J20 | G33: =IF(E33=0,"n/m",F33/E33) | H33: ='Entity Register'!K20
B34: 12 | C34: ='Entity Register'!A13 | D34: Restaurant | E34: ='Entity Register'!C13 | F34: ='Entity Register'!J13 | G34: =IF(E34=0,"n/m",F34/E34) | H34: ='Entity Register'!K13
B35: 13 | C35: ='Entity Register'!A18 | D35: Restaurant | E35: ='Entity Register'!C18 | F35: ='Entity Register'!J18 | G35: =IF(E35=0,"n/m",F35/E35) | H35: ='Entity Register'!K18
B36: 14 | C36: ='Entity Register'!A12 | D36: Restaurant | E36: ='Entity Register'!C12 | F36: ='Entity Register'!J12 | G36: =IF(E36=0,"n/m",F36/E36) | H36: ='Entity Register'!K12
B37: 15 | C37: ='Entity Register'!A14 | D37: Restaurant | E37: ='Entity Register'!C14 | F37: ='Entity Register'!J14 | G37: =IF(E37=0,"n/m",F37/E37) | H37: ='Entity Register'!K14
B38: 16 | C38: ='Entity Register'!A6 | D38: Real estate | E38: ='Entity Register'!C6 | F38: ='Entity Register'!J6 | G38: =IF(E38=0,"n/m",F38/E38) | H38: ='Entity Register'!K6
B39: Revenue = Operating Revenue only. A few HoldCos show $0 here but real profit in Net Income — they earn via intercompany dividends/interest (Investment & Other Income), not operating sales; their EBITDA Margin shows "n/m" rather than a misleading 0%.
B63: Business by Category
B64: ="Revenue & profitability mix across every industry in the group, fiscal year "&$K$2
B66: CONSTRUCTION | D66: HOTEL | F66: INVESTMENTS | H66: REAL ESTATE | J66: RENTAL | L66: RESTAURANT
B67: =-SUMIFS(Fact_TrialBalance[Amount],Fact_TrialBalance[Industry],"Construction",Fact_TrialBalance[Category],"Operating Revenue",Fact_TrialBalance[FiscalYear],$K$2)-SUMIFS(Fact_TrialBalance[Amount],Fact_TrialBalance[Industry],"Construction",Fact_TrialBalance[Category],"Investment & Other Income",Fact_TrialBalance[FiscalYear],$K$2) | D67: =-SUMIFS(Fact_TrialBalance[Amount],Fact_TrialBalance[Industry],"Hotel",Fact_TrialBalance[Category],"Operating Revenue",Fact_TrialBalance[FiscalYear],$K$2)-SUMIFS(Fact_TrialBalance[Amount],Fact_TrialBalance[Industry],"Hotel",Fact_TrialBalance[Category],"Investment & Other Income",Fact_TrialBalance[FiscalYear],$K$2) | F67: =-SUMIFS(Fact_TrialBalance[Amount],Fact_TrialBalance[Industry],"Investments",Fact_TrialBalance[Category],"Operating Revenue",Fact_TrialBalance[FiscalYear],$K$2)-SUMIFS(Fact_TrialBalance[Amount],Fact_TrialBalance[Industry],"Investments",Fact_TrialBalance[Category],"Investment & Other Income",Fact_TrialBalance[FiscalYear],$K$2) | H67: =-SUMIFS(Fact_TrialBalance[Amount],Fact_TrialBalance[Industry],"Real estate",Fact_TrialBalance[Category],"Operating Revenue",Fact_TrialBalance[FiscalYear],$K$2)-SUMIFS(Fact_TrialBalance[Amount],Fact_TrialBalance[Industry],"Real estate",Fact_TrialBalance[Category],"Investment & Other Income",Fact_TrialBalance[FiscalYear],$K$2) | J67: =-SUMIFS(Fact_TrialBalance[Amount],Fact_TrialBalance[Industry],"Rental",Fact_TrialBalance[Category],"Operating Revenue",Fact_TrialBalance[FiscalYear],$K$2)-SUMIFS(Fact_TrialBalance[Amount],Fact_TrialBalance[Industry],"Rental",Fact_TrialBalance[Category],"Investment & Other Income",Fact_TrialBalance[FiscalYear],$K$2) | L67: =-SUMIFS(Fact_TrialBalance[Amount],Fact_TrialBalance[Industry],"Restaurant",Fact_TrialBalance[Category],"Operating Revenue",Fact_TrialBalance[FiscalYear],$K$2)-SUMIFS(Fact_TrialBalance[Amount],Fact_TrialBalance[Industry],"Restaurant",Fact_TrialBalance[Category],"Investment & Other Income",Fact_TrialBalance[FiscalYear],$K$2)
B69: =IFERROR(-(SUMIFS(Fact_TrialBalance[Amount],Fact_TrialBalance[Industry],"Construction",Fact_TrialBalance[FiscalYear],$K$2)-SUMPRODUCT((Fact_TrialBalance[Industry]="Construction")*(Fact_TrialBalance[FiscalYear]=$K$2)*(ISNUMBER(MATCH(Fact_TrialBalance[Category],{"Interest & Financing","Amortization","Income Tax"},0)))*Fact_TrialBalance[Amount]))/B67,"n/m") | D69: =IFERROR(-(SUMIFS(Fact_TrialBalance[Amount],Fact_TrialBalance[Industry],"Hotel",Fact_TrialBalance[FiscalYear],$K$2)-SUMPRODUCT((Fact_TrialBalance[Industry]="Hotel")*(Fact_TrialBalance[FiscalYear]=$K$2)*(ISNUMBER(MATCH(Fact_TrialBalance[Category],{"Interest & Financing","Amortization","Income Tax"},0)))*Fact_TrialBalance[Amount]))/D67,"n/m") | F69: =IFERROR(-(SUMIFS(Fact_TrialBalance[Amount],Fact_TrialBalance[Industry],"Investments",Fact_TrialBalance[FiscalYear],$K$2)-SUMPRODUCT((Fact_TrialBalance[Industry]="Investments")*(Fact_TrialBalance[FiscalYear]=$K$2)*(ISNUMBER(MATCH(Fact_TrialBalance[Category],{"Interest & Financing","Amortization","Income Tax"},0)))*Fact_TrialBalance[Amount]))/F67,"n/m") | H69: =IFERROR(-(SUMIFS(Fact_TrialBalance[Amount],Fact_TrialBalance[Industry],"Real estate",Fact_TrialBalance[FiscalYear],$K$2)-SUMPRODUCT((Fact_TrialBalance[Industry]="Real estate")*(Fact_TrialBalance[FiscalYear]=$K$2)*(ISNUMBER(MATCH(Fact_TrialBalance[Category],{"Interest & Financing","Amortization","Income Tax"},0)))*Fact_TrialBalance[Amount]))/H67,"n/m") | J69: =IFERROR(-(SUMIFS(Fact_TrialBalance[Amount],Fact_TrialBalance[Industry],"Rental",Fact_TrialBalance[FiscalYear],$K$2)-SUMPRODUCT((Fact_TrialBalance[Industry]="Rental")*(Fact_TrialBalance[FiscalYear]=$K$2)*(ISNUMBER(MATCH(Fact_TrialBalance[Category],{"Interest & Financing","Amortization","Income Tax"},0)))*Fact_TrialBalance[Amount]))/J67,"n/m") | L69: =IFERROR(-(SUMIFS(Fact_TrialBalance[Amount],Fact_TrialBalance[Industry],"Restaurant",Fact_TrialBalance[FiscalYear],$K$2)-SUMPRODUCT((Fact_TrialBalance[Industry]="Restaurant")*(Fact_TrialBalance[FiscalYear]=$K$2)*(ISNUMBER(MATCH(Fact_TrialBalance[Category],{"Interest & Financing","Amortization","Income Tax"},0)))*Fact_TrialBalance[Amount]))/L67,"n/m")
C72: Industry | E72: Revenue
C73: Construction | E73: =B67
C74: Hotel | E74: =D67
C75: Investments | E75: =F67
C76: Real estate | E76: =H67
C77: Rental | E77: =J67
C78: Restaurant | E78: =L67

Sheet 04 Tax Position
L1: ← 01 Exec Summary
B2: RESTAURANT INDIAROSA 2 — CORPORATE TAXPREP EXPORT, CROSS-VALIDATED FIELDS ONLY
B4: Tax Position — Restaurant IndiaRosa 2 & Associated Group
B6: Every figure on this page was matched against an independently-known number before being trusted (per the handoff doc's validation rule) — nothing here is estimated or assumed.
B8: INCOME TAX, FY2025 | D8: FY24 NI (ACCOUNTING) | F8: FY24 NI (TAX BASIS) | H8: NCL B/F, START FY23
B9: =62548.0 | D9: =736959.0 | F9: =918366.0 | H9: =412649.0
B11: Matches CaseWare WTB | D11: Matches CaseWare WTB | F11: Federal T2 — differs from NI | H11: Federal — QC: 423,312
B14: IndiaRosa 2 — Net income for tax purposes (Federal T2), 3-year | G14: RDTOH / GRIP-CDA continuity
B15: Fiscal Year | C15: Net Income (tax basis) | G15: RDTOH balance: NOT FOUND CDA balance: NOT FOUND Checked every field description in this export for “RDTOH”, “refundable dividend tax on hand”, “CDA”, and “capital dividend” — zero matches, even with “Rolled Forward Data” checked in Xpress Filter. Per the handoff, this may need a dedicated Schedule 3 (RDTOH) / CDA continuity pull rather than the general Xpress Filter export. Not guessed or estimated here.
B16: FY2022 | C16: -59186
B17: FY2023 | C17: -1271829
B18: FY2024 | C18: 918366
B20: Not the formal 'Taxable Income' line (loss-carryforward application isn't shown in this export) — this is 'Net income for income tax purposes' per the T2. Genuinely differs from accounting net income; not treated as interchangeable.
B23: Associated Group — SBD & GRIP (from IndiaRosa 2's Taxprep SLIPA schedule, current year)
B24: Excludes IndiaRosa 2's own SBD claim — not found in this export.
B25: Entity | C25: Net Income (tax) | D25: Part I Tax | E25: SBD | G25: GRIP
B26: 9357-7427 Québec Inc. | C26: -3147 | D26: 0 | E26: 0 | G26: 0
B27: 9366-1676 Quebec Inc. | C27: -665484 | D27: 0 | E27: 0 | G27: 0
B28: 9425-4547 Québec Inc. | C28: 112788 | D28: 12155 | E28: 20146 | G28: 29568
B29: 9455-4169 Quebec Inc. | C29: -3065 | D29: 0 | E29: 0 | G29: 0
B30: 9455-4177 Quebec Inc. | C30: -3015 | D30: 0 | E30: 0 | G30: 0
B31: 9455-4201 Quebec inc. | C31: 577222 | D31: 0 | E31: 0 | G31: 0
B32: 9108-6876 Quebec Inc. | C32: 390551 | D32: 8318 | E32: 16540 | G32: 2325
B33: Bistro Guru Inc. | C33: -32467 | D33: 0 | E33: 0 | G33: 0
B34: 9096-0436 Quebec Inc. | C34: -21235 | D34: 0 | E34: 0 | G34: 0
B35: 9366-1049 Québec Inc. | C35: 312963 | D35: 35338 | E35: 36755 | G35: 229599
B36: 9098-0558 Quebec Inc. | C36: -13045 | D36: 0 | E36: 0 | G36: 0
B37: 2749-8567 Quebec Inc. | C37: 28760 | D37: 2864 | E37: 4594 | G37: 3297
... B39: 9525-2854 Québec Inc. | C39: -55143 | D39: 0 | E39: 0 | G39: 0
B40: Total | C40: =SUM(C26:C39) | D40: =SUM(D26:D39) | E40: =SUM(E26:E39) | G40: =SUM(G26:G39)

Sheet Entity Register
A1: Entity Register — driven by 01 Exec Summary's fiscal-year selector
A3: ← 01 Exec Summary
A4: EntityName | B4: Industry | C4: Revenue | D4: COGS | E4: Payroll | F4: Occupancy | G4: Interest & Financing | H4: Amortization | I4: Income Tax | J4: EBITDA | K4: Net Income
A5: 9357-7427 Québec Inc. - Sandhu H. | B5: Construction | C5: =-SUMIFS(Fact_TrialBalance[Amount],Fact_TrialBalance[EntityId],"9357-7427 QI",Fact_TrialBalance[Category],"Operating Revenue",Fact_TrialBalance[FiscalYear],'01 Exec Summary'!$K$2) | D5: =SUMIFS(Fact_TrialBalance[Amount],Fact_TrialBalance[EntityId],"9357-7427 QI",Fact_TrialBalance[Category],"COGS",Fact_TrialBalance[FiscalYear],'01 Exec Summary'!$K$2) | E5: =SUMIFS(Fact_TrialBalance[Amount],Fact_TrialBalance[EntityId],"9357-7427 QI",Fact_TrialBalance[Category],"Payroll & Benefits",Fact_TrialBalance[FiscalYear],'01 Exec Summary'!$K$2) | F5: =SUMIFS(Fact_TrialBalance[Amount],Fact_TrialBalance[EntityId],"9357-7427 QI",Fact_TrialBalance[Category],"Occupancy",Fact_TrialBalance[FiscalYear],'01 Exec Summary'!$K$2) | G5: =SUMIFS(Fact_TrialBalance[Amount],Fact_TrialBalance[EntityId],"9357-7427 QI",Fact_TrialBalance[Category],"Interest & Financing",Fact_TrialBalance[FiscalYear],'01 Exec Summary'!$K$2) | H5: =SUMIFS(Fact_TrialBalance[Amount],Fact_TrialBalance[EntityId],"9357-7427 QI",Fact_TrialBalance[Category],"Amortization",Fact_TrialBalance[FiscalYear],'01 Exec Summary'!$K$2) | I5: =SUMIFS(Fact_TrialBalance[Amount],Fact_TrialBalance[EntityId],"9357-7427 QI",Fact_TrialBalance[Category],"Income Tax",Fact_TrialBalance[FiscalYear],'01 Exec Summary'!$K$2) | J5: =-(SUMIFS(Fact_TrialBalance[Amount],Fact_TrialBalance[EntityId],"9357-7427 QI",Fact_TrialBalance[FiscalYear],'01 Exec Summary'!$K$2)-SUMPRODUCT((Fact_TrialBalance[EntityId]="9357-7427 QI")*(Fact_TrialBalance[FiscalYear]='01 Exec Summary'!$K$2)*(ISNUMBER(MATCH(Fact_TrialBalance[Category],{"Interest & Financing","Amortization","Income Tax"},0)))*Fact_TrialBalance[Amount])) | K5: =-SUMIFS(Fact_TrialBalance[Amount],Fact_TrialBalance[EntityId],"9357-7427 QI",Fact_TrialBalance[FiscalYear],'01 Exec Summary'!$K$2)
A6: 9366-1676 Québec Inc. - Sandhu G. | B6: Real estate | C6: =-SUMIFS(Fact_TrialBalance[Amount],Fact_TrialBalance[EntityId],"9366-1676 QI",Fact_TrialBalance[Category],"Operating Revenue",Fact_TrialBalance[FiscalYear],'01 Exec Summary'!$K$2) | D6: =SUMIFS(Fact_TrialBalance[Amount],Fact_TrialBalance[EntityId],"9366-1676 QI",Fact_TrialBalance[Category],"COGS",Fact_TrialBalance[FiscalYear],'01 Exec Summary'!$K$2) | E6: =SUMIFS(Fact_TrialBalance[Amount],Fact_TrialBalance[EntityId],"9366-1676 QI",Fact_TrialBalance[Category],"Payroll & Benefits",Fact_TrialBalance[FiscalYear],'01 Exec Summary'!$K$2) | F6: =SUMIFS(Fact_TrialBalance[Amount],Fact_TrialBalance[EntityId],"9366-1676 QI",Fact_TrialBalance[Category],"Occupancy",Fact_TrialBalance[FiscalYear],'01 Exec Summary'!$K$2) | G6: =SUMIFS(Fact_TrialBalance[Amount],Fact_TrialBalance[EntityId],"9366-1676 QI",Fact_TrialBalance[Category],"Interest & Financing",Fact_TrialBalance[FiscalYear],'01 Exec Summary'!$K$2) | H6: =SUMIFS(Fact_TrialBalance[Amount],Fact_TrialBalance[EntityId],"9366-1676 QI",Fact_TrialBalance[Category],"Amortization",Fact_TrialBalance[FiscalYear],'01 Exec Summary'!$K$2) | I6: =SUMIFS(Fact_TrialBalance[Amount],Fact_TrialBalance[EntityId],"9366-1676 QI",Fact_TrialBalance[Category],"Income Tax",Fact_TrialBalance[FiscalYear],'01 Exec Summary'!$K$2) | J6: =-(SUMIFS(Fact_TrialBalance[Amount],Fact_TrialBalance[EntityId],"9366-1676 QI",Fact_TrialBalance[FiscalYear],'01 Exec Summary'!$K$2)-SUMPRODUCT((Fact_TrialBalance[EntityId]="9366-1676 QI")*(Fact_TrialBalance[FiscalYear]='01 Exec Summary'!$K$2)*(ISNUMBER(MATCH(Fact_TrialBalance[Category],{"Interest & Financing","Amortization","Income Tax"},0)))*Fact_TrialBalance[Amount])) | K6: =-SUMIFS(Fact_TrialBalance[Amount],Fact_TrialBalance[EntityId],"9366-1676 QI",Fact_TrialBalance[FiscalYear],'01 Exec Summary'!$K$2)
A7: 9425-4547 Québec Inc. - Sandhu G | B7: Real estate | C7: =-SUMIFS(Fact_TrialBalance[Amount],Fact_TrialBalance[EntityId],"9425-4547 QI",Fact_TrialBalance[Category],"Operating Revenue",Fact_TrialBalance[FiscalYear],'01 Exec Summary'!$K$2) | D7: =SUMIFS(Fact_TrialBalance[Amount],Fact_TrialBalance[EntityId],"9425-4547 QI",Fact_TrialBalance[Category],"COGS",Fact_TrialBalance[FiscalYear],'01 Exec Summary'!$K$2) | E7: =SUMIFS(Fact_TrialBalance[Amount],Fact_TrialBalance[EntityId],"9425-4547 QI",Fact_TrialBalance[Category],"Payroll & Benefits",Fact_TrialBalance[FiscalYear],'01 Exec Summary'!$K$2) | F7: =SUMIFS(Fact_TrialBalance[Amount],Fact_TrialBalance[EntityId],"9425-4547 QI",Fact_TrialBalance[Category],"Occupancy",Fact_TrialBalance[FiscalYear],'01 Exec Summary'!$K$2) | G7: =SUMIFS(Fact_TrialBalance[Amount],Fact_TrialBalance[EntityId],"9425-4547 QI",Fact_TrialBalance[Category],"Interest & Financing",Fact_TrialBalance[FiscalYear],'01 Exec Summary'!$K$2) | H7: =SUMIFS(Fact_TrialBalance[Amount],Fact_TrialBalance[EntityId],"9425-4547 QI",Fact_TrialBalance[Category],"Amortization",Fact_TrialBalance[FiscalYear],'01 Exec Summary'!$K$2) | I7: =SUMIFS(Fact_TrialBalance[Amount],Fact_TrialBalance[EntityId],"9425-4547 QI",Fact_TrialBalance[Category],"Income Tax",Fact_TrialBalance[FiscalYear],'01 Exec Summary'!$K$2) | J7: =-(SUMIFS(Fact_TrialBalance[Amount],Fact_TrialBalance[EntityId],"9425-4547 QI",Fact_TrialBalance[FiscalYear],'01 Exec Summary'!$K$2)-SUMPRODUCT((Fact_TrialBalance[EntityId]="9425-4547 QI")*(Fact_TrialBalance[FiscalYear]='01 Exec Summary'!$K$2)*(ISNUMBER(MATCH(Fact_TrialBalance[Category],{"Interest & Financing","Amortization","Income Tax"},0)))*Fact_TrialBalance[Amount])) | K7: =-SUMIFS(Fact_TrialBalance[Amount],Fact_TrialBalance[EntityId],"9425-4547 QI",Fact_TrialBalance[FiscalYear],'01 Exec Summary'!$K$2)
A8: 9455-4169 Québec Inc. - Sandhu | B8: Investments | C8: =-SUMIFS(Fact_TrialBalance[Amount],Fact_TrialBalance[EntityId],"9455-4169 QI",Fact_TrialBalance[Category],"Operating Revenue",Fact_TrialBalance[FiscalYear],'01 Exec Summary'!$K$2) | D8: =SUMIFS(Fact_TrialBalance[Amount],Fact_TrialBalance[EntityId],"9455-4169 QI",Fact_TrialBalance[Category],"COGS",Fact_TrialBalance[FiscalYear],'01 Exec Summary'!$K$2) | E8: =SUMIFS(Fact_TrialBalance[Amount],Fact_TrialBalance[EntityId],"9455-4169 QI",Fact_TrialBalance[Category],"Payroll & Benefits",Fact_TrialBalance[FiscalYear],'01 Exec Summary'!$K$2) | F8: =SUMIFS(Fact_TrialBalance[Amount],Fact_TrialBalance[EntityId],"9455-4169 QI",Fact_TrialBalance[Category],"Occupancy",Fact_TrialBalance[FiscalYear],'01 Exec Summary'!$K$2) | G8: =SUMIFS(Fact_TrialBalance[Amount],Fact_TrialBalance[EntityId],"9455-4169 QI",Fact_TrialBalance[Category],"Interest & Financing",Fact_TrialBalance[FiscalYear],'01 Exec Summary'!$K$2) | H8: =SUMIFS(Fact_TrialBalance[Amount],Fact_TrialBalance[EntityId],"9455-4169 QI",Fact_TrialBalance[Category],"Amortization",Fact_TrialBalance[FiscalYear],'01 Exec Summary'!$K$2) | I8: =SUMIFS(Fact_TrialBalance[Amount],Fact_TrialBalance[EntityId],"9455-4169 QI",Fact_TrialBalance[Category],"Income Tax",Fact_TrialBalance[FiscalYear],'01 Exec Summary'!$K$2) | J8: =-(SUMIFS(Fact_TrialBalance[Amount],Fact_TrialBalance[EntityId],"9455-4169 QI",Fact_TrialBalance[FiscalYear],'01 Exec Summary'!$K$2)-SUMPRODUCT((Fact_TrialBalance[EntityId]="9455-4169 QI")*(Fact_TrialBalance[FiscalYear]='01 Exec Summary'!$K$2)*(ISNUMBER(MATCH(Fact_TrialBalance[Category],{"Interest & Financing","Amortization","Income Tax"},0)))*Fact_TrialBalance[Amount])) | K8: =-SUMIFS(Fact_TrialBalance[Amount],Fact_TrialBalance[EntityId],"9455-4169 QI",Fact_TrialBalance[FiscalYear],'01 Exec Summary'!$K$2)
A9: 9455-4177 Québec Inc. - Sandhu H. | B9: Investments | C9: =-SUMIFS(Fact_TrialBalance[Amount],Fact_TrialBalance[EntityId],"9455-4177 QI",Fact_TrialBalance[Category],"Operating Revenue",Fact_TrialBalance[FiscalYear],'01 Exec Summary'!$K$2) | D9: =SUMIFS(Fact_TrialBalance[Amount],Fact_TrialBalance[EntityId],"9455-4177 QI",Fact_TrialBalance[Category],"COGS",Fact_TrialBalance[FiscalYear],'01 Exec Summary'!$K$2) | E9: =SUMIFS(Fact_TrialBalance[Amount],Fact_TrialBalance[EntityId],"9455-4177 QI",Fact_TrialBalance[Category],"Payroll & Benefits",Fact_TrialBalance[FiscalYear],'01 Exec Summary'!$K$2) | F9: =SUMIFS(Fact_TrialBalance[Amount],Fact_TrialBalance[EntityId],"9455-4177 QI",Fact_TrialBalance[Category],"Occupancy",Fact_TrialBalance[FiscalYear],'01 Exec Summary'!$K$2) | G9: =SUMIFS(Fact_TrialBalance[Amount],Fact_TrialBalance[EntityId],"9455-4177 QI",Fact_TrialBalance[Category],"Interest & Financing",Fact_TrialBalance[FiscalYear],'01 Exec Summary'!$K$2) | H9: =SUMIFS(Fact_TrialBalance[Amount],Fact_TrialBalance[EntityId],"9455-4177 QI",Fact_TrialBalance[Category],"Amortization",Fact_TrialBalance[FiscalYear],'01 Exec Summary'!$K$2) | I9: =SUMIFS(Fact_TrialBalance[Amount],Fact_TrialBalance[EntityId],"9455-4177 QI",Fact_TrialBalance[Category],"Income Tax",Fact_TrialBalance[FiscalYear],'01 Exec Summary'!$K$2) | J9: =-(SUMIFS(Fact_TrialBalance[Amount],Fact_TrialBalance[EntityId],"9455-4177 QI",Fact_TrialBalance[FiscalYear],'01 Exec Summary'!$K$2)-SUMPRODUCT((Fact_TrialBalance[EntityId]="9455-4177 QI")*(Fact_TrialBalance[FiscalYear]='01 Exec Summary'!$K$2)*(ISNUMBER(MATCH(Fact_TrialBalance[Category],{"Interest & Financing","Amortization","Income Tax"},0)))*Fact_TrialBalance[Amount])) | K9: =-SUMIFS(Fact_TrialBalance[Amount],Fact_TrialBalance[EntityId],"9455-4177 QI",Fact_TrialBalance[FiscalYear],'01 Exec Summary'!$K$2)
A10: 9455-4201 Québec Inc. - Sandhu G | B10: Investments | C10: =-SUMIFS(Fact_TrialBalance[Amount],Fact_TrialBalance[EntityId],"9455-4201 QI",Fact_TrialBalance[Category],"Operating Revenue",Fact_TrialBalance[FiscalYear],'01 Exec Summary'!$K$2) | D10: =SUMIFS(Fact_TrialBalance[Amount],Fact_TrialBalance[EntityId],"9455-4201 QI",Fact_TrialBalance[Category],"COGS",Fact_TrialBalance[FiscalYear],'01 Exec Summary'!$K$2) | E10: =SUMIFS(Fact_TrialBalance[Amount],Fact_TrialBalance[EntityId],"9455-4201 QI",Fact_TrialBalance[Category],"Payroll & Benefits",Fact_TrialBalance[FiscalYear],'01 Exec Summary'!$K$2) | F10: =SUMIFS(Fact_TrialBalance[Amount],Fact_TrialBalance[EntityId],"9455-4201 QI",Fact_TrialBalance[Category],"Occupancy",Fact_TrialBalance[FiscalYear],'01 Exec Summary'!$K$2) | G10: =SUMIFS(Fact_TrialBalance[Amount],Fact_TrialBalance[EntityId],"9455-4201 QI",Fact_TrialBalance[Category],"Interest & Financing",Fact_TrialBalance[FiscalYear],'01 Exec Summary'!$K$2) | H10: =SUMIFS(Fact_TrialBalance[Amount],Fact_TrialBalance[EntityId],"9455-4201 QI",Fact_TrialBalance[Category],"Amortization",Fact_TrialBalance[FiscalYear],'01 Exec Summary'!$K$2) | I10: =SUMIFS(Fact_TrialBalance[Amount],Fact_TrialBalance[EntityId],"9455-4201 QI",Fact_TrialBalance[Category],"Income Tax",Fact_TrialBalance[FiscalYear],'01 Exec Summary'!$K$2) | J10: =-(SUMIFS(Fact_TrialBalance[Amount],Fact_TrialBalance[EntityId],"9455-4201 QI",Fact_TrialBalance[FiscalYear],'01 Exec Summary'!$K$2)-SUMPRODUCT((Fact_TrialBalance[EntityId]="9455-4201 QI")*(Fact_TrialBalance[FiscalYear]='01 Exec Summary'!$K$2)*(ISNUMBER(MATCH(Fact_TrialBalance[Category],{"Interest & Financing","Amortization","Income Tax"},0)))*Fact_TrialBalance[Amount])) | K10: =-SUMIFS(Fact_TrialBalance[Amount],Fact_TrialBalance[EntityId],"9455-4201 QI",Fact_TrialBalance[FiscalYear],'01 Exec Summary'!$K$2)
A11: Auberge du Carre St-Louis | B11: Hotel | C11: =-SUMIFS(Fact_TrialBalance[Amount],Fact_TrialBalance[EntityId],"9108-6876 QI",Fact_TrialBalance[Category],"Operating Revenue",Fact_TrialBalance[FiscalYear],'01 Exec Summary'!$K$2) | D11: =SUMIFS(Fact_TrialBalance[Amount],Fact_TrialBalance[EntityId],"9108-6876 QI",Fact_TrialBalance[Category],"COGS",Fact_TrialBalance[FiscalYear],'01 Exec Summary'!$K$2) | E11: =SUMIFS(Fact_TrialBalance[Amount],Fact_TrialBalance[EntityId],"9108-6876 QI",Fact_TrialBalance[Category],"Payroll & Benefits",Fact_TrialBalance[FiscalYear],'01 Exec Summary'!$K$2) | F11: =SUMIFS(Fact_TrialBalance[Amount],Fact_TrialBalance[EntityId],"9108-6876 QI",Fact_TrialBalance[Category],"Occupancy",Fact_TrialBalance[FiscalYear],'01 Exec Summary'!$K$2) | G11: =SUMIFS(Fact_TrialBalance[Amount],Fact_TrialBalance[EntityId],"9108-6876 QI",Fact_TrialBalance[Category],"Interest & Financing",Fact_TrialBalance[FiscalYear],'01 Exec Summary'!$K$2) | H11: =SUMIFS(Fact_TrialBalance[Amount],Fact_TrialBalance[EntityId],"9108-6876 QI",Fact_TrialBalance[Category],"Amortization",Fact_TrialBalance[FiscalYear],'01 Exec Summary'!$K$2) | I11: =SUMIFS(Fact_TrialBalance[Amount],Fact_TrialBalance[EntityId],"9108-6876 QI",Fact_TrialBalance[Category],"Income Tax",Fact_TrialBalance[FiscalYear],'01 Exec Summary'!$K$2) | J11: =-(SUMIFS(Fact_TrialBalance[Amount],Fact_TrialBalance[EntityId],"9108-6876 QI",Fact_TrialBalance[FiscalYear],'01 Exec Summary'!$K$2)-SUMPRODUCT((Fact_TrialBalance[EntityId]="9108-6876 QI")*(Fact_TrialBalance[FiscalYear]='01 Exec Summary'!$K$2)*(ISNUMBER(MATCH(Fact_TrialBalance[Category],{"Interest & Financing","Amortization","Income Tax"},0)))*Fact_TrialBalance[Amount])) | K11: =-SUMIFS(Fact_TrialBalance[Amount],Fact_TrialBalance[EntityId],"9108-6876 QI",Fact_TrialBalance[FiscalYear],'01 Exec Summary'!$K$2)
A12: Bistro Guru Inc. | B12: Restaurant | C12: =-SUMIFS(Fact_TrialBalance[Amount],Fact_TrialBalance[EntityId],"N/A_BisGur",Fact_TrialBalance[Category],"Operating Revenue",Fact_TrialBalance[FiscalYear],'01 Exec Summary'!$K$2) | D12: =SUMIFS(Fact_TrialBalance[Amount],Fact_TrialBalance[EntityId],"N/A_BisGur",Fact_TrialBalance[Category],"COGS",Fact_TrialBalance[FiscalYear],'01 Exec Summary'!$K$2) | E12: =SUMIFS(Fact_TrialBalance[Amount],Fact_TrialBalance[EntityId],"N/A_BisGur",Fact_TrialBalance[Category],"Payroll & Benefits",Fact_TrialBalance[FiscalYear],'01 Exec Summary'!$K$2) | F12: =SUMIFS(Fact_TrialBalance[Amount],Fact_TrialBalance[EntityId],"N/A_BisGur",Fact_TrialBalance[Category],"Occupancy",Fact_TrialBalance[FiscalYear],'01 Exec Summary'!$K$2) | G12: =SUMIFS(Fact_TrialBalance[Amount],Fact_TrialBalance[EntityId],"N/A_BisGur",Fact_TrialBalance[Category],"Interest & Financing",Fact_TrialBalance[FiscalYear],'01 Exec Summary'!$K$2) | H12: =SUMIFS(Fact_TrialBalance[Amount],Fact_TrialBalance[EntityId],"N/A_BisGur",Fact_TrialBalance[Category],"Amortization",Fact_TrialBalance[FiscalYear],'01 Exec Summary'!$K$2) | I12: =SUMIFS(Fact_TrialBalance[Amount],Fact_TrialBalance[EntityId],"N/A_BisGur",Fact_TrialBalance[Category],"Income Tax",Fact_TrialBalance[FiscalYear],'01 Exec Summary'!$K$2) | J12: =-(SUMIFS(Fact_TrialBalance[Amount],Fact_TrialBalance[EntityId],"N/A_BisGur",Fact_TrialBalance[FiscalYear],'01 Exec Summary'!$K$2)-SUMPRODUCT((Fact_TrialBalance[EntityId]="N/A_BisGur")*(Fact_TrialBalance[FiscalYear]='01 Exec Summary'!$K$2)*(ISNUMBER(MATCH(Fact_TrialBalance[Category],{"Interest & Financing","Amortization","Income Tax"},0)))*Fact_TrialBalance[Amount])) | K12: =-SUMIFS(Fact_TrialBalance[Amount],Fact_TrialBalance[EntityId],"N/A_BisGur",Fact_TrialBalance[FiscalYear],'01 Exec Summary'!$K$2)
A13: Lobby Bar Lounge | B13: Restaurant | C13: =-SUMIFS(Fact_TrialBalance[Amount],Fact_TrialBalance[EntityId],"9096-0436 QI",Fact_TrialBalance[Category],"Operating Revenue",Fact_TrialBalance[FiscalYear],'01 Exec Summary'!$K$2) | D13: =SUMIFS(Fact_TrialBalance[Amount],Fact_TrialBalance[EntityId],"9096-0436 QI",Fact_TrialBalance[Category],"COGS",Fact_TrialBalance[FiscalYear],'01 Exec Summary'!$K$2) | E13: =SUMIFS(Fact_TrialBalance[Amount],Fact_TrialBalance[EntityId],"9096-0436 QI",Fact_TrialBalance[Category],"Payroll & Benefits",Fact_TrialBalance[FiscalYear],'01 Exec Summary'!$K$2) | F13: =SUMIFS(Fact_TrialBalance[Amount],Fact_TrialBalance[EntityId],"9096-0436 QI",Fact_TrialBalance[Category],"Occupancy",Fact_TrialBalance[FiscalYear],'01 Exec Summary'!$K$2) | G13: =SUMIFS(Fact_TrialBalance[Amount],Fact_TrialBalance[EntityId],"9096-0436 QI",Fact_TrialBalance[Category],"Interest & Financing",Fact_TrialBalance[FiscalYear],'01 Exec Summary'!$K$2) | H13: =SUMIFS(Fact_TrialBalance[Amount],Fact_TrialBalance[EntityId],"9096-0436 QI",Fact_TrialBalance[Category],"Amortization",Fact_TrialBalance[FiscalYear],'01 Exec Summary'!$K$2) | I13: =SUMIFS(Fact_TrialBalance[Amount],Fact_TrialBalance[EntityId],"9096-0436 QI",Fact_TrialBalance[Category],"Income Tax",Fact_TrialBalance[FiscalYear],'01 Exec Summary'!$K$2) | J13: =-(SUMIFS(Fact_TrialBalance[Amount],Fact_TrialBalance[EntityId],"9096-0436 QI",Fact_TrialBalance[FiscalYear],'01 Exec Summary'!$K$2)-SUMPRODUCT((Fact_TrialBalance[EntityId]="9096-0436 QI")*(Fact_TrialBalance[FiscalYear]='01 Exec Summary'!$K$2)*(ISNUMBER(MATCH(Fact_TrialBalance[Category],{"Interest & Financing","Amortization","Income Tax"},0)))*Fact_TrialBalance[Amount])) | K13: =-SUMIFS(Fact_TrialBalance[Amount],Fact_TrialBalance[EntityId],"9096-0436 QI",Fact_TrialBalance[FiscalYear],'01 Exec Summary'!$K$2)
A14: Restaurant Héritaj | B14: Restaurant | C14: =-SUMIFS(Fact_TrialBalance[Amount],Fact_TrialBalance[EntityId],"9504-7510 QI",Fact_TrialBalance[Category],"Operating Revenue",Fact_TrialBalance[FiscalYear],'01 Exec Summary'!$K$2) | D14: =SUMIFS(Fact_TrialBalance[Amount],Fact_TrialBalance[EntityId],"9504-7510 QI",Fact_TrialBalance[Category],"COGS",Fact_TrialBalance[FiscalYear],'01 Exec Summary'!$K$2) | E14: =SUMIFS(Fact_TrialBalance[Amount],Fact_TrialBalance[EntityId],"9504-7510 QI",Fact_TrialBalance[Category],"Payroll & Benefits",Fact_TrialBalance[FiscalYear],'01 Exec Summary'!$K$2) | F14: =SUMIFS(Fact_TrialBalance[Amount],Fact_TrialBalance[EntityId],"9504-7510 QI",Fact_TrialBalance[Category],"Occupancy",Fact_TrialBalance[FiscalYear],'01 Exec Summary'!$K$2) | G14: =SUMIFS(Fact_TrialBalance[Amount],Fact_TrialBalance[EntityId],"9504-7510 QI",Fact_TrialBalance[Category],"Interest & Financing",Fact_TrialBalance[FiscalYear],'01 Exec Summary'!$K$2) | H14: =SUMIFS(Fact_TrialBalance[Amount],Fact_TrialBalance[EntityId],"9504-7510 QI",Fact_TrialBalance[Category],"Amortization",Fact_TrialBalance[FiscalYear],'01 Exec Summary'!$K$2) | I14: =SUMIFS(Fact_TrialBalance[Amount],Fact_TrialBalance[EntityId],"9504-7510 QI",Fact_TrialBalance[Category],"Income Tax",Fact_TrialBalance[FiscalYear],'01 Exec Summary'!$K$2) | J14: =-(SUMIFS(Fact_TrialBalance[Amount],Fact_TrialBalance[EntityId],"9504-7510 QI",Fact_TrialBalance[FiscalYear],'01 Exec Summary'!$K$2)-SUMPRODUCT((Fact_TrialBalance[EntityId]="9504-7510 QI")*(Fact_TrialBalance[FiscalYear]='01 Exec Summary'!$K$2)*(ISNUMBER(MATCH(Fact_TrialBalance[Category],{"Interest & Financing","Amortization","Income Tax"},0)))*Fact_TrialBalance[Amount])) | K14: =-SUMIFS(Fact_TrialBalance[Amount],Fact_TrialBalance[EntityId],"9504-7510 QI",Fact_TrialBalance[FiscalYear],'01 Exec Summary'!$K$2)
A15: Restaurant Indiarosa II | B15: Restaurant | C15: =-SUMIFS(Fact_TrialBalance[Amount],Fact_TrialBalance[EntityId],"9455-8236 QI",Fact_TrialBalance[Category],"Operating Revenue",Fact_TrialBalance[FiscalYear],'01 Exec Summary'!$K$2) | D15: =SUMIFS(Fact_TrialBalance[Amount],Fact_TrialBalance[EntityId],"9455-8236 QI",Fact_TrialBalance[Category],"COGS",Fact_TrialBalance[FiscalYear],'01 Exec Summary'!$K$2) | E15: =SUMIFS(Fact_TrialBalance[Amount],Fact_TrialBalance[EntityId],"9455-8236 QI",Fact_TrialBalance[Category],"Payroll & Benefits",Fact_TrialBalance[FiscalYear],'01 Exec Summary'!$K$2) | F15: =SUMIFS(Fact_TrialBalance[Amount],Fact_TrialBalance[EntityId],"9455-8236 QI",Fact_TrialBalance[Category],"Occupancy",Fact_TrialBalance[FiscalYear],'01 Exec Summary'!$K$2) | G15: =SUMIFS(Fact_TrialBalance[Amount],Fact_TrialBalance[EntityId],"9455-8236 QI",Fact_TrialBalance[Category],"Interest & Financing",Fact_TrialBalance[FiscalYear],'01 Exec Summary'!$K$2) | H15: =SUMIFS(Fact_TrialBalance[Amount],Fact_TrialBalance[EntityId],"9455-8236 QI",Fact_TrialBalance[Category],"Amortization",Fact_TrialBalance[FiscalYear],'01 Exec Summary'!$K$2) | I15: =SUMIFS(Fact_TrialBalance[Amount],Fact_TrialBalance[EntityId],"9455-8236 QI",Fact_TrialBalance[Category],"Income Tax",Fact_TrialBalance[FiscalYear],'01 Exec Summary'!$K$2) | J15: =-(SUMIFS(Fact_TrialBalance[Amount],Fact_TrialBalance[EntityId],"9455-8236 QI",Fact_TrialBalance[FiscalYear],'01 Exec Summary'!$K$2)-SUMPRODUCT((Fact_TrialBalance[EntityId]="9455-8236 QI")*(Fact_TrialBalance[FiscalYear]='01 Exec Summary'!$K$2)*(ISNUMBER(MATCH(Fact_TrialBalance[Category],{"Interest & Financing","Amortization","Income Tax"},0)))*Fact_TrialBalance[Amount])) | K15: =-SUMIFS(Fact_TrialBalance[Amount],Fact_TrialBalance[EntityId],"9455-8236 QI",Fact_TrialBalance[FiscalYear],'01 Exec Summary'!$K$2)
A16: Restaurant Indiarosa III | B16: Restaurant | C16: =-SUMIFS(Fact_TrialBalance[Amount],Fact_TrialBalance[EntityId],"9525-2854 QI",Fact_TrialBalance[Category],"Operating Revenue",Fact_TrialBalance[FiscalYear],'01 Exec Summary'!$K$2) | D16: =SUMIFS(Fact_TrialBalance[Amount],Fact_TrialBalance[EntityId],"9525-2854 QI",Fact_TrialBalance[Category],"COGS",Fact_TrialBalance[FiscalYear],'01 Exec Summary'!$K$2) | E16: =SUMIFS(Fact_TrialBalance[Amount],Fact_TrialBalance[EntityId],"9525-2854 QI",Fact_TrialBalance[Category],"Payroll & Benefits",Fact_TrialBalance[FiscalYear],'01 Exec Summary'!$K$2) | F16: =SUMIFS(Fact_TrialBalance[Amount],Fact_TrialBalance[EntityId],"9525-2854 QI",Fact_TrialBalance[Category],"Occupancy",Fact_TrialBalance[FiscalYear],'01 Exec Summary'!$K$2) | G16: =SUMIFS(Fact_TrialBalance[Amount],Fact_TrialBalance[EntityId],"9525-2854 QI",Fact_TrialBalance[Category],"Interest & Financing",Fact_TrialBalance[FiscalYear],'01 Exec Summary'!$K$2) | H16: =SUMIFS(Fact_TrialBalance[Amount],Fact_TrialBalance[EntityId],"9525-2854 QI",Fact_TrialBalance[Category],"Amortization",Fact_TrialBalance[FiscalYear],'01 Exec Summary'!$K$2) | I16: =SUMIFS(Fact_TrialBalance[Amount],Fact_TrialBalance[EntityId],"9525-2854 QI",Fact_TrialBalance[Category],"Income Tax",Fact_TrialBalance[FiscalYear],'01 Exec Summary'!$K$2) | J16: =-(SUMIFS(Fact_TrialBalance[Amount],Fact_TrialBalance[EntityId],"9525-2854 QI",Fact_TrialBalance[FiscalYear],'01 Exec Summary'!$K$2)-SUMPRODUCT((Fact_TrialBalance[EntityId]="9525-2854 QI")*(Fact_TrialBalance[FiscalYear]='01 Exec Summary'!$K$2)*(ISNUMBER(MATCH(Fact_TrialBalance[Category],{"Interest & Financing","Amortization","Income Tax"},0)))*Fact_TrialBalance[Amount])) | K16: =-SUMIFS(Fact_TrialBalance[Amount],Fact_TrialBalance[EntityId],"9525-2854 QI",Fact_TrialBalance[FiscalYear],'01 Exec Summary'!$K$2)
A17: Restaurant Indiarosa | B17: Restaurant | C17: =-SUMIFS(Fact_TrialBalance[Amount],Fact_TrialBalance[EntityId],"9366-1049 QI",Fact_TrialBalance[Category],"Operating Revenue",Fact_TrialBalance[FiscalYear],'01 Exec Summary'!$K$2) | D17: =SUMIFS(Fact_TrialBalance[Amount],Fact_TrialBalance[EntityId],"9366-1049 QI",Fact_TrialBalance[Category],"COGS",Fact_TrialBalance[FiscalYear],'01 Exec Summary'!$K$2) | E17: =SUMIFS(Fact_TrialBalance[Amount],Fact_TrialBalance[EntityId],"9366-1049 QI",Fact_TrialBalance[Category],"Payroll & Benefits",Fact_TrialBalance[FiscalYear],'01 Exec Summary'!$K$2) | F17: =SUMIFS(Fact_TrialBalance[Amount],Fact_TrialBalance[EntityId],"9366-1049 QI",Fact_TrialBalance[Category],"Occupancy",Fact_TrialBalance[FiscalYear],'01 Exec Summary'!$K$2) | G17: =SUMIFS(Fact_TrialBalance[Amount],Fact_TrialBalance[EntityId],"9366-1049 QI",Fact_TrialBalance[Category],"Interest & Financing",Fact_TrialBalance[FiscalYear],'01 Exec Summary'!$K$2) | H17: =SUMIFS(Fact_TrialBalance[Amount],Fact_TrialBalance[EntityId],"9366-1049 QI",Fact_TrialBalance[Category],"Amortization",Fact_TrialBalance[FiscalYear],'01 Exec Summary'!$K$2) | I17: =SUMIFS(Fact_TrialBalance[Amount],Fact_TrialBalance[EntityId],"9366-1049 QI",Fact_TrialBalance[Category],"Income Tax",Fact_TrialBalance[FiscalYear],'01 Exec Summary'!$K$2) | J17: =-(SUMIFS(Fact_TrialBalance[Amount],Fact_TrialBalance[EntityId],"9366-1049 QI",Fact_TrialBalance[FiscalYear],'01 Exec Summary'!$K$2)-SUMPRODUCT((Fact_TrialBalance[EntityId]="9366-1049 QI")*(Fact_TrialBalance[FiscalYear]='01 Exec Summary'!$K$2)*(ISNUMBER(MATCH(Fact_TrialBalance[Category],{"Interest & Financing","Amortization","Income Tax"},0)))*Fact_TrialBalance[Amount])) | K17: =-SUMIFS(Fact_TrialBalance[Amount],Fact_TrialBalance[EntityId],"9366-1049 QI",Fact_TrialBalance[FiscalYear],'01 Exec Summary'!$K$2)
